<robot name="k1">

  <link name="base_link">
    <inertial>
      <origin xyz="3.1237E-05 -2.6609E-18 0.043467" rpy="0 0 0" />
      <mass value="0.24447" />
      <inertia ixx="0.00022866" ixy="-4.4957E-21" ixz="-1.1924E-22" iyy="0.00016383" iyz="-2.1079E-21" izz="0.00013299" />
    </inertial>
    <visual>
      <origin xyz="0 0 0" rpy="0 0 0" />
      <geometry>
        <mesh filename="package://k1_description/meshes/visual/base_link.STL" />
      </geometry>
      <material name="">
        <color rgba="0.79216 0.81961 0.93333 1" />
      </material>
    </visual>
    <collision>
      <origin xyz="0 0 0" rpy="0 0 0" />
      <geometry>
        <mesh filename="package://k1_description/meshes/collision/base_link.STL" />
      </geometry>
    </collision>
  </link>
  <link name="right_hip_link">
    <inertial>
      <origin xyz="-0.0091911 0.00013724 0.0068616" rpy="0 0 0" />
      <mass value="0.027822" />
      <inertia ixx="2.9324E-06" ixy="5.4126E-22" ixz="8.2036E-08" iyy="5.289E-06" iyz="-5.5232E-22" izz="5.521E-06" />
    </inertial>
    <visual>
      <origin xyz="0 0 0" rpy="0 0 0" />
      <geometry>
        <mesh filename="package://k1_description/meshes/visual/right_hip_link.STL" />
      </geometry>
      <material name="">
        <color rgba="0.25098 0.25098 0.25098 1" />
      </material>
    </visual>
    <collision>
      <origin xyz="0 0 0" rpy="0 0 0" />
      <geometry>
        <mesh filename="package://k1_description/meshes/collision/right_hip_link.STL" />
      </geometry>
    </collision>
  </link>
  <joint name="right_hip" type="continuous">
    <origin xyz="0.0005 -0.015 -0.02" rpy="-3.1416 0 1.5708" />
    <parent link="base_link" />
    <child link="right_hip_link" />
    <axis xyz="0 1 0" />
    <limit lower="0" upper="0" effort="0" velocity="0" />
  </joint>
  <link name="right_thigh_link">
    <inertial>
      <origin xyz="0.00048354 -1.0408E-17 0.028801" rpy="0 0 0" />
      <mass value="0.044066" />
      <inertia ixx="6.9987E-06" ixy="2.4849E-23" ixz="6.6075E-07" iyy="5.8317E-06" iyz="-2.5887E-22" izz="4.6055E-06" />
    </inertial>
    <visual>
      <origin xyz="0 0 0" rpy="0 0 0" />
      <geometry>
        <mesh filename="package://k1_description/meshes/visual/right_thigh_link.STL" />
      </geometry>
      <material name="">
        <color rgba="0.25098 0.25098 0.25098 1" />
      </material>
    </visual>
    <collision>
      <origin xyz="0 0 0" rpy="0 0 0" />
      <geometry>
        <mesh filename="package://k1_description/meshes/collision/right_thigh_link.STL" />
      </geometry>
    </collision>
  </link>
  <joint name="right_thigh" type="continuous">
    <origin xyz="-0.0094505 0.0005 0.033316" rpy="0.031659 0.025339 1.5716" />
    <parent link="right_hip_link" />
    <child link="right_thigh_link" />
    <axis xyz="0 1 0" />
    <limit lower="0" upper="0" effort="0" velocity="0" />
  </joint>
  <link name="right_knee_link">
    <inertial>
      <origin xyz="-0.0178121084477415 2.77555756156289E-17 0.0307655812522569" rpy="0 0 0" />
      <mass value="0.032371769923242" />
      <inertia ixx="6.0588731794123E-06" ixy="-3.9527863778785E-22" ixz="3.4680753923887E-07" iyy="3.93488969546397E-06" iyz="4.3890533855335E-22" izz="4.63947306958273E-06" />
    </inertial>
    <visual>
      <origin xyz="0 0 0" rpy="0 0 0" />
      <geometry>
        <mesh filename="package://k1_description/meshes/visual/right_knee_link.STL" />
      </geometry>
      <material name="">
        <color rgba="0.752941176470588 1 1 1" />
      </material>
    </visual>
    <collision>
      <origin xyz="0 0 0" rpy="0 0 0" />
      <geometry>
        <mesh filename="package://k1_description/meshes/collision/right_knee_link.STL" />
      </geometry>
    </collision>
  </link>
  <joint name="right_knee" type="continuous">
    <origin xyz="-0.0021501 0 0.055492" rpy="0 0.49935 -3.1416" />
    <parent link="right_thigh_link" />
    <child link="right_knee_link" />
    <axis xyz="0 1 0" />
    <limit lower="0" upper="0" effort="0" velocity="0" />
  </joint>
  <link name="right_calf_link">
    <inertial>
      <origin xyz="-0.009582 0.0010801 -0.024645" rpy="0 0 0" />
      <mass value="0.027822" />
      <inertia ixx="5.3156E-06" ixy="1.0464E-21" ixz="7.4393E-08" iyy="2.9298E-06" iyz="-2.516E-22" izz="5.497E-06" />
    </inertial>
    <visual>
      <origin xyz="0 0 0" rpy="0 0 0" />
      <geometry>
        <mesh filename="package://k1_description/meshes/visual/right_calf_link.STL" />
      </geometry>
      <material name="">
        <color rgba="0.75294 1 1 1" />
      </material>
    </visual>
    <collision>
      <origin xyz="0 0 0" rpy="0 0 0" />
      <geometry>
        <mesh filename="package://k1_description/meshes/collision/right_calf_link.STL" />
      </geometry>
    </collision>
  </link>
  <joint name="right_calf" type="continuous">
    <origin xyz="-0.023084 0 0.051939" rpy="3.1416 -0.11317 0" />
    <parent link="right_knee_link" />
    <child link="right_calf_link" />
    <axis xyz="0 1 0" />
    <limit lower="0" upper="0" effort="0" velocity="0" />
  </joint>
  <link name="right_ankle_link">
    <inertial>
      <origin xyz="-0.0134919017266966 0.00459336693369054 0.0134840145322273" rpy="0 0 0" />
      <mass value="0.132188163411726" />
      <inertia ixx="0.000105111740356927" ixy="-2.67854466622719E-10" ixz="4.02982212640105E-07" iyy="4.22846170003843E-05" iyz="1.35813174315627E-10" izz="0.000136756609487253" />
    </inertial>
    <visual>
      <origin xyz="0 0 0" rpy="0 0 0" />
      <geometry>
        <mesh filename="package://k1_description/meshes/visual/right_ankle_link.STL" />
      </geometry>
      <material name="">
        <color rgba="0.752941176470588 1 1 1" />
      </material>
    </visual>
    <collision>
      <origin xyz="0 0 0" rpy="0 0 0" />
      <geometry>
        <mesh filename="package://k1_description/meshes/collision/right_ankle_link.STL" />
      </geometry>
    </collision>
  </link>
  <joint name="right_ankle" type="continuous">
    <origin xyz="-0.012051 -0.0075 -0.030737" rpy="2.7982 0 -1.5708" />
    <parent link="right_calf_link" />
    <child link="right_ankle_link" />
    <axis xyz="0 1 0" />
    <limit lower="0" upper="0" effort="0" velocity="0" />
  </joint>
  <link name="left_hip_link">
    <inertial>
      <origin xyz="0.00574384356514769 0.000137242116570632 -0.00899186986767261" rpy="0 0 0" />
      <mass value="0.027821769923242" />
      <inertia ixx="5.52363659732332E-06" ixy="2.35404777695923E-22" ixz="9.52912065661088E-22" iyy="5.28896445958682E-06" iyz="-7.01815773253074E-22" izz="2.92981364310441E-06" />
    </inertial>
    <visual>
      <origin xyz="0 0 0" rpy="0 0 0" />
      <geometry>
        <mesh filename="package://k1_description/meshes/visual/left_hip_link.STL" />
      </geometry>
      <material name="">
        <color rgba="0.250980392156863 0.250980392156863 0.250980392156863 1" />
      </material>
    </visual>
    <collision>
      <origin xyz="0 0 0" rpy="0 0 0" />
      <geometry>
        <mesh filename="package://k1_description/meshes/collision/left_hip_link.STL" />
      </geometry>
    </collision>
  </link>
  <joint name="left_hip" type="continuous">
    <origin xyz="0.0005 0.015 -0.02" rpy="3.1416 1.3958 1.5708" />
    <parent link="base_link" />
    <child link="left_hip_link" />
    <axis xyz="0 1 0" />
    <limit lower="0" upper="0" effort="0" velocity="0" />
  </joint>
  <link name="left_thigh_link">
    <inertial>
      <origin xyz="0.000483541080447515 -1.38777878078145E-17 -0.0288011243914165" rpy="0 0 0" />
      <mass value="0.0440662654824574" />
      <inertia ixx="6.99871657924005E-06" ixy="-1.30252055807653E-21" ixz="-6.60751594534272E-07" iyy="5.83167629890069E-06" iyz="1.22954384106141E-21" izz="4.6055287326144E-06" />
    </inertial>
    <visual>
      <origin xyz="0 0 0" rpy="0 0 0" />
      <geometry>
        <mesh filename="package://k1_description/meshes/visual/left_thigh_link.STL" />
      </geometry>
      <material name="">
        <color rgba="0.250980392156863 0.250980392156863 0.250980392156863 1" />
      </material>
    </visual>
    <collision>
      <origin xyz="0 0 0" rpy="0 0 0" />
      <geometry>
        <mesh filename="package://k1_description/meshes/collision/left_thigh_link.STL" />
      </geometry>
    </collision>
  </link>
  <joint name="left_thigh" type="continuous">
    <origin xyz="0.03 0.0005 -0.009" rpy="-1.5708 0 1.4529" />
    <parent link="left_hip_link" />
    <child link="left_thigh_link" />
    <axis xyz="0 1 0" />
    <limit lower="0" upper="0" effort="0" velocity="0" />
  </joint>
  <link name="left_knee_link">
    <inertial>
      <origin xyz="-0.0159002354975483 -6.76542155630955E-16 -0.0317958284727074" rpy="0 0 0" />
      <mass value="0.0323717699232421" />
      <inertia ixx="6.09585578173946E-06" ixy="-9.75086376578192E-22" ixz="-2.57710392869743E-07" iyy="3.93488969546397E-06" iyz="-1.37120055400643E-21" izz="4.60249046725557E-06" />
    </inertial>
    <visual>
      <origin xyz="0 0 0" rpy="0 0 0" />
      <geometry>
        <mesh filename="package://k1_description/meshes/visual/left_knee_link.STL" />
      </geometry>
      <material name="">
        <color rgba="0.752941176470588 1 1 1" />
      </material>
    </visual>
    <collision>
      <origin xyz="0 0 0" rpy="0 0 0" />
      <geometry>
        <mesh filename="package://k1_description/meshes/collision/left_knee_link.STL" />
      </geometry>
    </collision>
  </link>
  <joint name="left_knee" type="continuous">
    <origin xyz="-0.0021501 0 -0.055492" rpy="0 -0.49935 3.1416" />
    <parent link="left_thigh_link" />
    <child link="left_knee_link" />
    <axis xyz="0 1 0" />
    <limit lower="0" upper="0" effort="0" velocity="0" />
  </joint>
  <link name="left_calf_link">
    <inertial>
      <origin xyz="-0.00690141207525505 0.00108014351796133 0.0255261573931621" rpy="0 0 0" />
      <mass value="0.0278217699232421" />
      <inertia ixx="5.30185932211653E-06" ixy="3.09254745805148E-23" ixz="-5.34769808048693E-08" iyy="2.92981364310441E-06" iyz="-8.94604079450337E-22" izz="5.51074173479362E-06" />
    </inertial>
    <visual>
      <origin xyz="0 0 0" rpy="0 0 0" />
      <geometry>
        <mesh filename="package://k1_description/meshes/visual/left_calf_link.STL" />
      </geometry>
      <material name="">
        <color rgba="0.752941176470588 1 1 1" />
      </material>
    </visual>
    <collision>
      <origin xyz="0 0 0" rpy="0 0 0" />
      <geometry>
        <mesh filename="package://k1_description/meshes/collision/left_calf_link.STL" />
      </geometry>
    </collision>
  </link>
  <joint name="left_calf" type="continuous">
    <origin xyz="-0.019869 0 -0.053251" rpy="-3.1416 0.052065 0" />
    <parent link="left_knee_link" />
    <child link="left_calf_link" />
    <axis xyz="0 1 0" />
    <limit lower="0" upper="0" effort="0" velocity="0" />
  </joint>
  <link name="left_ankle_link">
    <inertial>
      <origin xyz="-0.0136213334288442 -0.00459337841653701 -0.013353320848436" rpy="0 0 0" />
      <mass value="0.132188114966052" />
      <inertia ixx="0.000136753876292704" ixy="-5.26733657769073E-10" ixz="-7.25991197394409E-07" iyy="4.22864611143807E-05" iyz="-7.24960113429766E-11" izz="0.000105128445504655" />
    </inertial>
    <visual>
      <origin xyz="0 0 0" rpy="0 0 0" />
      <geometry>
        <mesh filename="package://k1_description/meshes/visual/left_ankle_link.STL" />
      </geometry>
      <material name="">
        <color rgba="0.752941176470588 1 1 1" />
      </material>
    </visual>
    <collision>
      <origin xyz="0 0 0" rpy="0 0 0" />
      <geometry>
        <mesh filename="package://k1_description/meshes/collision/left_ankle_link.STL" />
      </geometry>
    </collision>
  </link>
  <joint name="left_ankle" type="continuous">
    <origin xyz="-0.0087077 -0.0075 0.031846" rpy="1.5708 1.3342 0" />
    <parent link="left_calf_link" />
    <child link="left_ankle_link" />
    <axis xyz="0 1 0" />
    <limit lower="0" upper="0" effort="0" velocity="0" />
  </joint>
  <link name="right_arm_link">
    <inertial>
      <origin xyz="-9.99200722162641E-16 0.0259259508257144 -2.15105711021124E-16" rpy="0 0 0" />
      <mass value="0.00763663718201332" />
      <inertia ixx="2.43758966616897E-06" ixy="2.93020214434485E-22" ixz="4.12200417999712E-09" iyy="2.02189199404243E-06" iyz="5.46092272261234E-23" izz="9.35393567758914E-07" />
    </inertial>
    <visual>
      <origin xyz="0 0 0" rpy="0 0 0" />
      <geometry>
        <mesh filename="package://k1_description/meshes/visual/right_arm_link.STL" />
      </geometry>
      <material name="">
        <color rgba="0.752941176470588 1 1 1" />
      </material>
    </visual>
    <collision>
      <origin xyz="0 0 0" rpy="0 0 0" />
      <geometry>
        <mesh filename="package://k1_description/meshes/collision/right_arm_link.STL" />
      </geometry>
    </collision>
  </link>
  <joint name="right_shoulder" type="continuous">
    <origin xyz="-0.007 -0.026 0.075" rpy="3.1416 -1.5708 0" />
    <parent link="base_link" />
    <child link="right_arm_link" />
    <axis xyz="0 1 0" />
    <limit lower="0" upper="0" effort="0" velocity="0" />
  </joint>
  <link name="right_arm_upper_link">
    <inertial>
      <origin xyz="-0.0267099408480544 -5.91540705308091E-16 -0.00839330007950644" rpy="0 0 0" />
      <mass value="0.0404127433991118" />
      <inertia ixx="5.33571477961189E-06" ixy="-3.15155813382704E-22" ixz="-1.56386748236192E-07" iyy="6.27306084712395E-06" iyz="-1.94387443949962E-22" izz="5.78424046197137E-06" />
    </inertial>
    <visual>
      <origin xyz="0 0 0" rpy="0 0 0" />
      <geometry>
        <mesh filename="package://k1_description/meshes/visual/right_arm_upper_link.STL" />
      </geometry>
      <material name="">
        <color rgba="0.250980392156863 0.250980392156863 0.250980392156863 1" />
      </material>
    </visual>
    <collision>
      <origin xyz="0 0 0" rpy="0 0 0" />
      <geometry>
        <mesh filename="package://k1_description/meshes/collision/right_arm_upper_link.STL" />
      </geometry>
    </collision>
  </link>
  <joint name="right_upper" type="continuous">
    <origin xyz="0 0.0350000000000004 0" rpy="-1.56989921107132 -0.00259316215202615 -0.33306656840474" />
    <parent link="right_arm_link" />
    <child link="right_arm_upper_link" />
    <axis xyz="0 1 0" />
    <limit lower="0" upper="0" effort="0" velocity="0" />
  </joint>
  <link name="right_arm_lower_link">
    <inertial>
      <origin xyz="0.0182616337014053 0.00084071649884114 -4.33680868994202E-18" rpy="0 0 0" />
      <mass value="0.0290848600660391" />
      <inertia ixx="2.72498939319332E-06" ixy="-1.67669592897643E-07" ixz="2.5146290621612E-22" iyy="4.0538898836655E-06" iyz="3.57083530681485E-22" izz="4.64311633086366E-06" />
    </inertial>
    <visual>
      <origin xyz="0 0 0" rpy="0 0 0" />
      <geometry>
        <mesh filename="package://k1_description/meshes/visual/right_arm_lower_link.STL" />
      </geometry>
      <material name="">
        <color rgba="0.250980392156863 0.250980392156863 0.250980392156863 1" />
      </material>
    </visual>
    <collision>
      <origin xyz="0 0 0" rpy="0 0 0" />
      <geometry>
        <mesh filename="package://k1_description/meshes/collision/right_arm_lower_link.STL" />
      </geometry>
    </collision>
  </link>
  <joint name="right_arm_lower" type="continuous">
    <origin xyz="-0.0667804560220959 0 -0.0209850111622641" rpy="1.5864967516128 0.304075688258208 -3.0891987069566" />
    <parent link="right_arm_upper_link" />
    <child link="right_arm_lower_link" />
    <axis xyz="0 1 0" />
    <limit lower="0" upper="0" effort="0" velocity="0" />
  </joint>
  <link name="left_arm_link">
    <inertial>
      <origin xyz="-7.7715611723761E-16 -0.0259259508257144 3.45209971719385E-16" rpy="0 0 0" />
      <mass value="0.00763663718201333" />
      <inertia ixx="2.43758966616897E-06" ixy="2.47506888618435E-22" ixz="-4.12200417999841E-09" iyy="2.02189199404244E-06" iyz="1.16991672016122E-22" izz="9.35393567758914E-07" />
    </inertial>
    <visual>
      <origin xyz="0 0 0" rpy="0 0 0" />
      <geometry>
        <mesh filename="package://k1_description/meshes/visual/left_arm_link.STL" />
      </geometry>
      <material name="">
        <color rgba="0.752941176470588 1 1 1" />
      </material>
    </visual>
    <collision>
      <origin xyz="0 0 0" rpy="0 0 0" />
      <geometry>
        <mesh filename="package://k1_description/meshes/collision/left_arm_link.STL" />
      </geometry>
    </collision>
  </link>
  <joint name="left_shoulder" type="continuous">
    <origin xyz="-0.007 0.026 0.075" rpy="3.1416 -1.5708 0" />
    <parent link="base_link" />
    <child link="left_arm_link" />
    <axis xyz="0 1 0" />
    <limit lower="0" upper="0" effort="0" velocity="0" />
  </joint>
  <link name="left_arm_upper_link">
    <inertial>
      <origin xyz="-0.0267099408480542 -4.86589935011494E-16 -0.00839330007950634" rpy="0 0 0" />
      <mass value="0.0404127433991118" />
      <inertia ixx="5.33571477961189E-06" ixy="8.43724224804088E-22" ixz="-1.56386748236191E-07" iyy="6.27306084712395E-06" iyz="3.66441011360991E-22" izz="5.78424046197137E-06" />
    </inertial>
    <visual>
      <origin xyz="0 0 0" rpy="0 0 0" />
      <geometry>
        <mesh filename="package://k1_description/meshes/visual/left_arm_upper_link.STL" />
      </geometry>
      <material name="">
        <color rgba="0.250980392156863 0.250980392156863 0.250980392156863 1" />
      </material>
    </visual>
    <collision>
      <origin xyz="0 0 0" rpy="0 0 0" />
      <geometry>
        <mesh filename="package://k1_description/meshes/collision/left_arm_upper_link.STL" />
      </geometry>
    </collision>
  </link>
  <joint name="left_arm_upper" type="continuous">
    <origin xyz="0 -0.0350000000000004 0" rpy="1.57169344251847 0.00259316215202667 0.33306656840474" />
    <parent link="left_arm_link" />
    <child link="left_arm_upper_link" />
    <axis xyz="0 1 0" />
    <limit lower="0" upper="0" effort="0" velocity="0" />
  </joint>
  <link name="left_arm_lower_link">
    <inertial>
      <origin xyz="0.0182616337014054 0.000840716498841161 -6.93889390390723E-18" rpy="0 0 0" />
      <mass value="0.0290848600660391" />
      <inertia ixx="2.72498939319332E-06" ixy="-1.67669592897644E-07" ixz="7.94093388050907E-23" iyy="4.0538898836655E-06" iyz="8.69185878034236E-22" izz="4.64311633086366E-06" />
    </inertial>
    <visual>
      <origin xyz="0 0 0" rpy="0 0 0" />
      <geometry>
        <mesh filename="package://k1_description/meshes/visual/left_arm_lower_link.STL" />
      </geometry>
      <material name="">
        <color rgba="0.250980392156863 0.250980392156863 0.250980392156863 1" />
      </material>
    </visual>
    <collision>
      <origin xyz="0 0 0" rpy="0 0 0" />
      <geometry>
        <mesh filename="package://k1_description/meshes/collision/left_arm_lower_link.STL" />
      </geometry>
    </collision>
  </link>
  <joint name="left_arm_lower" type="continuous">
    <origin xyz="-0.0667804560220957 0 -0.020985011162264" rpy="1.5864967516128 0.304075688258208 -3.0891987069566" />
    <parent link="left_arm_upper_link" />
    <child link="left_arm_lower_link" />
    <axis xyz="0 1 0" />
    <limit lower="0" upper="0" effort="0" velocity="0" />
  </joint>
  <link name="head_link">
    <inertial>
      <origin xyz="0 0 0" rpy="0 0 0" />
      <mass value="0" />
      <inertia ixx="0" ixy="0" ixz="0" iyy="0" iyz="0" izz="0" />
    </inertial>
    <visual>
      <origin xyz="0 0 0" rpy="0 0 0" />
      <geometry>
        <mesh filename="package://k1_description/meshes/visual/head_link.STL" />
      </geometry>
      <material name="">
        <color rgba="1 1 1 1" />
      </material>
    </visual>
    <collision>
      <origin xyz="0 0 0" rpy="0 0 0" />
      <geometry>
        <mesh filename="package://k1_description/meshes/collision/head_link.STL" />
      </geometry>
    </collision>
  </link>
  <joint name="head" type="revolute">
    <origin xyz="-0.011 0 0.086" rpy="-1.5707963267949 0 1.5707963267949" />
    <parent link="base_link" />
    <child link="head_link" />
    <axis xyz="0 1 0" />
    <limit lower="0" upper="0" effort="0" velocity="0" />
  </joint>
</robot>
