<robot name="k1">

  <link name="base_link">
    <inertial>
      <origin xyz="-4.61950778389125E-19 2.73283908536959E-18 0.0470916230366492" rpy="0 0 0" />
      <mass value="0.2292" />
      <inertia ixx="0.00015895767591623" ixy="3.7704942585474E-21" ixz="-2.14051822428277E-21" iyy="0.00022678767591623" iyz="1.20880355025952E-21" izz="0.00012895" />
    </inertial>
    <visual>
      <origin xyz="0 0 0" rpy="0 0 0" />
      <geometry>
        <mesh filename="package://k1_description/meshes/visual/base_link.STL" />
      </geometry>
      <material name="">
        <color rgba="0.792156862745098 0.819607843137255 0.933333333333333 1" />
      </material>
    </visual>
    <collision>
      <origin xyz="0 0 0" rpy="0 0 0" />
      <geometry>
        <mesh filename="package://k1_description/meshes/collision/base_link.STL" />
      </geometry>
    </collision>
  </link>
  <link name="right_hip_link">
    <inertial>
      <origin xyz="0.00940359621738448 -0.000137242116570632 0.00656729626457146" rpy="0 0 0" />
      <mass value="0.027821769923242" />
      <inertia ixx="2.92981364310441E-06" ixy="4.30908198288843E-22" ixz="6.28657265540301E-22" iyy="5.28896445958682E-06" iyz="9.46658009525752E-23" izz="5.52363659732332E-06" />
    </inertial>
    <visual>
      <origin xyz="0 0 0" rpy="0 0 0" />
      <geometry>
        <mesh filename="package://k1_description/meshes/visual/right_hip_link.STL" />
      </geometry>
      <material name="">
        <color rgba="0.250980392156863 0.250980392156863 0.250980392156863 1" />
      </material>
    </visual>
    <collision>
      <origin xyz="0 0 0" rpy="0 0 0" />
      <geometry>
        <mesh filename="package://k1_description/meshes/collision/right_hip_link.STL" />
      </geometry>
    </collision>
  </link>
  <joint name="right_hip_joint" type="revolute">
    <origin xyz="-0.015 -0.000499999999999993 -0.02" rpy="-3.14159265358979 0.0316484172966858 -3.14159265358979" />
    <parent link="base_link" />
    <child link="right_hip_link" />
    <axis xyz="0 1 0" />
    <limit lower="-6.0" upper="6.0" effort="1000" velocity="3.0" />
  </joint>
  <link name="right_thigh_link">
    <inertial>
      <origin xyz="-0.000246681744016047 -3.46944695195361E-18 0.0288041268970871" rpy="0 0 0" />
      <mass value="0.0440662654824574" />
      <inertia ixx="6.96369137755179E-06" ixy="4.38207832004734E-22" ixz="7.20546870045399E-07" iyy="5.83167629890068E-06" iyz="-4.71683349965899E-24" izz="4.64055393430265E-06" />
    </inertial>
    <visual>
      <origin xyz="0 0 0" rpy="0 0 0" />
      <geometry>
        <mesh filename="package://k1_description/meshes/visual/right_thigh_link.STL" />
      </geometry>
      <material name="">
        <color rgba="0.250980392156863 0.250980392156863 0.250980392156863 1" />
      </material>
    </visual>
    <collision>
      <origin xyz="0 0 0" rpy="0 0 0" />
      <geometry>
        <mesh filename="package://k1_description/meshes/collision/right_thigh_link.STL" />
      </geometry>
    </collision>
  </link>
  <joint name="right_thigh_joint" type="revolute">
    <origin xyz="0.0105 -0.000499999999999989 0.033" rpy="0 0.0253512899928625 -1.5707963267949" />
    <parent link="right_hip_link" />
    <child link="right_thigh_link" />
    <axis xyz="0 1 0" />
    <limit lower="-6.0" upper="6.0" effort="1000" velocity="3.0" />
  </joint>
  <link name="right_knee_link">
    <inertial>
      <origin xyz="0.0355383336616086 -3.12250225675825E-17 -0.000905007016273815" rpy="0 0 0" />
      <mass value="0.032371769923242" />
      <inertia ixx="4.67335720190332E-06" ixy="7.12136216752866E-22" ixz="-4.08928448493292E-07" iyy="3.93488969546397E-06" iyz="-6.52115381615019E-22" izz="6.0249890470917E-06" />
    </inertial>
    <visual>
      <origin xyz="0 0 0" rpy="0 0 0" />
      <geometry>
        <mesh filename="package://k1_description/meshes/visual/right_knee_link.STL" />
      </geometry>
      <material name="">
        <color rgba="0.752941176470588 1 1 1" />
      </material>
    </visual>
    <collision>
      <origin xyz="0 0 0" rpy="0 0 0" />
      <geometry>
        <mesh filename="package://k1_description/meshes/collision/right_knee_link.STL" />
      </geometry>
    </collision>
  </link>
  <joint name="right_knee_joint" type="revolute">
    <origin xyz="-0.00355599647142655 0 0.055419370059348" rpy="-3.14159265358978 -1.54544503680202 3.14159265358978" />
    <parent link="right_thigh_link" />
    <child link="right_knee_link" />
    <axis xyz="0 1 0" />
    <limit lower="-6.0" upper="6.0" effort="1000" velocity="3.0" />
  </joint>
  <link name="right_calf_link">
    <inertial>
      <origin xyz="0.0264395340671427 0.00108014351796196 0.000406495024938089" rpy="0 0 0" />
      <mass value="0.027821769923242" />
      <inertia ixx="5.52320669558642E-06" ixy="3.31056529427015E-22" ixz="1.00349959696259E-08" iyy="2.9298136431044E-06" iyz="3.62681967144928E-23" izz="5.28939436132371E-06" />
    </inertial>
    <visual>
      <origin xyz="0 0 0" rpy="0 0 0" />
      <geometry>
        <mesh filename="package://k1_description/meshes/visual/right_calf_link.STL" />
      </geometry>
      <material name="">
        <color rgba="0.752941176470588 1 1 1" />
      </material>
    </visual>
    <collision>
      <origin xyz="0 0 0" rpy="0 0 0" />
      <geometry>
        <mesh filename="package://k1_description/meshes/collision/right_calf_link.STL" />
      </geometry>
    </collision>
  </link>
  <joint name="right_calf_joint" type="revolute">
    <origin xyz="0.0566505085564426 0 0.00460572071266819" rpy="0 0 0" />
    <parent link="right_knee_link" />
    <child link="right_calf_link" />
    <axis xyz="0 1 0" />
    <limit lower="-6.0" upper="6.0" effort="1000" velocity="3.0" />
  </joint>
  <link name="right_ankle_link">
    <inertial>
      <origin xyz="0.0136623267443019 -0.00459336936624942 0.0133113128666117" rpy="0 0 0" />
      <mass value="0.132188160242468" />
      <inertia ixx="0.000105106606233086" ixy="-2.6922058885189E-10" ixz="-3.57117309042543E-10" iyy="4.22846167628333E-05" iyz="-1.31879399966339E-10" izz="0.000136761741778018" />
    </inertial>
    <visual>
      <origin xyz="0 0 0" rpy="0 0 0" />
      <geometry>
        <mesh filename="package://k1_description/meshes/visual/right_ankle_link.STL" />
      </geometry>
      <material name="">
        <color rgba="0.752941176470588 1 1 1" />
      </material>
    </visual>
    <collision>
      <origin xyz="0 0 0" rpy="0 0 0" />
      <geometry>
        <mesh filename="package://k1_description/meshes/collision/right_ankle_link.STL" />
      </geometry>
    </collision>
  </link>
  <joint name="right_ankle_joint" type="revolute">
    <origin xyz="0.0330125603748861 -0.0074999999999983 0.000413349119391304" rpy="1.52798571545966 -0.000544427216642011 1.55808767255617" />
    <parent link="right_calf_link" />
    <child link="right_ankle_link" />
    <axis xyz="0 1 0" />
    <limit lower="-6.0" upper="6.0" effort="1000" velocity="3.0" />
  </joint>
  <link name="left_hip_link">
    <inertial>
      <origin xyz="0.0089918698676726 0.000137242116570587 0.00656729626457131" rpy="0 0 0" />
      <mass value="0.027821769923242" />
      <inertia ixx="2.92981364310441E-06" ixy="1.05304755240537E-22" ixz="-6.61744490042422E-22" iyy="5.28896445958682E-06" iyz="1.63447699966183E-22" izz="5.52363659732332E-06" />
    </inertial>
    <visual>
      <origin xyz="0 0 0" rpy="0 0 0" />
      <geometry>
        <mesh filename="package://k1_description/meshes/visual/left_hip_link.STL" />
      </geometry>
      <material name="">
        <color rgba="0.250980392156863 0.250980392156863 0.250980392156863 1" />
      </material>
    </visual>
    <collision>
      <origin xyz="0 0 0" rpy="0 0 0" />
      <geometry>
        <mesh filename="package://k1_description/meshes/collision/left_hip_link.STL" />
      </geometry>
    </collision>
  </link>
  <joint name="left_hip_joint" type="revolute">
    <origin xyz="0.015 -0.000500000000000029 -0.02" rpy="3.14159265358979 -0.0788882616806473 0" />
    <parent link="base_link" />
    <child link="left_hip_link" />
    <axis xyz="0 1 0" />
    <limit lower="-6.0" upper="6.0" effort="1000" velocity="3.0" />
  </joint>
  <link name="left_thigh_link">
    <inertial>
      <origin xyz="0.0288011243914165 1.04083408558608E-17 -0.000483541080447512" rpy="0 0 0" />
      <mass value="0.0440662654824575" />
      <inertia ixx="4.6055287326144E-06" ixy="1.12360003625057E-21" ixz="-6.60751594534273E-07" iyy="5.83167629890069E-06" iyz="-1.04244405181093E-21" izz="6.99871657924005E-06" />
    </inertial>
    <visual>
      <origin xyz="0 0 0" rpy="0 0 0" />
      <geometry>
        <mesh filename="package://k1_description/meshes/visual/left_thigh_link.STL" />
      </geometry>
      <material name="">
        <color rgba="0.250980392156863 0.250980392156863 0.250980392156863 1" />
      </material>
    </visual>
    <collision>
      <origin xyz="0 0 0" rpy="0 0 0" />
      <geometry>
        <mesh filename="package://k1_description/meshes/collision/left_thigh_link.STL" />
      </geometry>
    </collision>
  </link>
  <joint name="left_thigh_joint" type="revolute">
    <origin xyz="0.00899999999999999 0.000499999999999904 0.0329999999999999" rpy="1.5707963267949 -1.5707963267949 0" />
    <parent link="left_hip_link" />
    <child link="left_thigh_link" />
    <axis xyz="0 1 0" />
    <limit lower="-6.0" upper="6.0" effort="1000" velocity="3.0" />
  </joint>
  <link name="left_knee_link">
    <inertial>
      <origin xyz="0.0129798147259141 -6.93889390390723E-17 -0.033095567782171" rpy="0 0 0" />
      <mass value="0.032371769923242" />
      <inertia ixx="5.52787586698897E-06" ixy="-4.37696008678394E-22" ixz="7.69425088650609E-07" iyy="3.93488969546397E-06" iyz="-4.82918274474036E-23" izz="5.17047038200604E-06" />
    </inertial>
    <visual>
      <origin xyz="0 0 0" rpy="0 0 0" />
      <geometry>
        <mesh filename="package://k1_description/meshes/visual/left_knee_link.STL" />
      </geometry>
      <material name="">
        <color rgba="0.752941176470588 1 1 1" />
      </material>
    </visual>
    <collision>
      <origin xyz="0 0 0" rpy="0 0 0" />
      <geometry>
        <mesh filename="package://k1_description/meshes/collision/left_knee_link.STL" />
      </geometry>
    </collision>
  </link>
  <joint name="left_knee_joint" type="revolute">
    <origin xyz="0.0554917017754941 0 0.0021500517992317" rpy="0 -1.01236160973997 0" />
    <parent link="left_thigh_link" />
    <child link="left_knee_link" />
    <axis xyz="0 1 0" />
    <limit lower="-6.0" upper="6.0" effort="1000" velocity="3.0" />
  </joint>
  <link name="left_calf_link">
    <inertial>
      <origin xyz="-0.000725515766858749 -0.00108014351796073 -0.0264327037354286" rpy="0 0 0" />
      <mass value="0.0278217699232421" />
      <inertia ixx="5.28896445958682E-06" ixy="-1.26537476861723E-22" ixz="2.77932685817817E-22" iyy="2.92981364310441E-06" iyz="1.23463790543838E-21" izz="5.52363659732332E-06" />
    </inertial>
    <visual>
      <origin xyz="0 0 0" rpy="0 0 0" />
      <geometry>
        <mesh filename="package://k1_description/meshes/visual/left_calf_link.STL" />
      </geometry>
      <material name="">
        <color rgba="0.752941176470588 1 1 1" />
      </material>
    </visual>
    <collision>
      <origin xyz="0 0 0" rpy="0 0 0" />
      <geometry>
        <mesh filename="package://k1_description/meshes/collision/left_calf_link.STL" />
      </geometry>
    </collision>
  </link>
  <joint name="left_calf_joint" type="revolute">
    <origin xyz="0.0262634559672917 0 -0.0504055915910211" rpy="0 -0.581500701027345 0" />
    <parent link="left_knee_link" />
    <child link="left_calf_link" />
    <axis xyz="0 1 0" />
    <limit lower="-6.0" upper="6.0" effort="1000" velocity="3.0" />
  </joint>
  <link name="left_ankle_link">
    <inertial>
      <origin xyz="-0.0136623074420151 0.0045933649358092 -0.0133113309298591" rpy="0 0 0" />
      <mass value="0.13218815029551" />
      <inertia ixx="0.000105106587445954" ixy="2.7045501953536E-10" ixz="3.33073194093848E-10" iyy="4.22846005451457E-05" iyz="-1.28132118283693E-10" izz="0.000136761711395075" />
    </inertial>
    <visual>
      <origin xyz="0 0 0" rpy="0 0 0" />
      <geometry>
        <mesh filename="package://k1_description/meshes/visual/left_ankle_link.STL" />
      </geometry>
      <material name="">
        <color rgba="0.752941176470588 1 1 1" />
      </material>
    </visual>
    <collision>
      <origin xyz="0 0 0" rpy="0 0 0" />
      <geometry>
        <mesh filename="package://k1_description/meshes/collision/left_ankle_link.STL" />
      </geometry>
    </collision>
  </link>
  <joint name="left_ankle_joint" type="revolute">
    <origin xyz="-0.000999999999999996 0.00750000000000001 -0.033" rpy="0 0.0595977859512234 1.5707963267949" />
    <parent link="left_calf_link" />
    <child link="left_ankle_link" />
    <axis xyz="0 1 0" />
    <limit lower="-6.0" upper="6.0" effort="1000" velocity="3.0" />
  </joint>
  <link name="right_shoulder_link">
    <inertial>
      <origin xyz="-2.14238349283136E-16 0.0259259508257144 9.85322934354826E-16" rpy="0 0 0" />
      <mass value="0.00763663718201332" />
      <inertia ixx="9.35393567758914E-07" ixy="5.90338332070666E-23" ixz="-4.12200417999754E-09" iyy="2.02189199404243E-06" iyz="-2.29670259357228E-22" izz="2.43758966616897E-06" />
    </inertial>
    <visual>
      <origin xyz="0 0 0" rpy="0 0 0" />
      <geometry>
        <mesh filename="package://k1_description/meshes/visual/right_shoulder_link.STL" />
      </geometry>
      <material name="">
        <color rgba="0.752941176470588 1 1 1" />
      </material>
    </visual>
    <collision>
      <origin xyz="0 0 0" rpy="0 0 0" />
      <geometry>
        <mesh filename="package://k1_description/meshes/collision/right_shoulder_link.STL" />
      </geometry>
    </collision>
  </link>
  <joint name="right_shoulder_joint" type="revolute">
    <origin xyz="-0.026 0.00700000000000001 0.075" rpy="-3.14159265358979 0 -1.5707963267949" />
    <parent link="base_link" />
    <child link="right_shoulder_link" />
    <axis xyz="0 1 0" />
    <limit lower="-6.0" upper="6.0" effort="1000" velocity="3.0" />
  </joint>
  <link name="right_upper_arm_link">
    <inertial>
      <origin xyz="-1.56819002228303E-15 -7.01695646032618E-16 0.0279976503716149" rpy="0 0 0" />
      <mass value="0.0404127433991118" />
      <inertia ixx="5.83338324794276E-06" ixy="-9.23081864820894E-23" ixz="2.74785814906162E-21" iyy="6.27306084712395E-06" iyz="3.58996385848014E-22" izz="5.28657199364051E-06" />
    </inertial>
    <visual>
      <origin xyz="0 0 0" rpy="0 0 0" />
      <geometry>
        <mesh filename="package://k1_description/meshes/visual/right_upper_arm_link.STL" />
      </geometry>
      <material name="">
        <color rgba="0.250980392156863 0.250980392156863 0.250980392156863 1" />
      </material>
    </visual>
    <collision>
      <origin xyz="0 0 0" rpy="0 0 0" />
      <geometry>
        <mesh filename="package://k1_description/meshes/collision/right_upper_arm_link.STL" />
      </geometry>
    </collision>
  </link>
  <joint name="right_upper_arm_joint" type="revolute">
    <origin xyz="0 0.0349999999999999 0" rpy="-0.00274508024652193 0.0285971009019822 1.57071783596033" />
    <parent link="right_shoulder_link" />
    <child link="right_upper_arm_link" />
    <axis xyz="0 1 0" />
    <limit lower="-6.0" upper="6.0" effort="1000" velocity="3.0" />
  </joint>
  <link name="right_lower_arm_link">
    <inertial>
      <origin xyz="0.0182616337014053 0.00084071649884114 -5.20417042793042E-18" rpy="0 0 0" />
      <mass value="0.0290848600660391" />
      <inertia ixx="2.72498939319332E-06" ixy="-1.67669592897643E-07" ixz="2.77932685817817E-22" iyy="4.0538898836655E-06" iyz="3.52559886706586E-22" izz="4.64311633086366E-06" />
    </inertial>
    <visual>
      <origin xyz="0 0 0" rpy="0 0 0" />
      <geometry>
        <mesh filename="package://k1_description/meshes/visual/right_lower_arm_link.STL" />
      </geometry>
      <material name="">
        <color rgba="0.250980392156863 0.250980392156863 0.250980392156863 1" />
      </material>
    </visual>
    <collision>
      <origin xyz="0 0 0" rpy="0 0 0" />
      <geometry>
        <mesh filename="package://k1_description/meshes/collision/right_lower_arm_link.STL" />
      </geometry>
    </collision>
  </link>
  <joint name="right_lower_arm_joint" type="revolute">
    <origin xyz="0 0 0.0699999999999956" rpy="0 -1.52080805151912 -1.57079632679487" />
    <parent link="right_upper_arm_link" />
    <child link="right_lower_arm_link" />
    <axis xyz="0 1 0" />
    <limit lower="-6.0" upper="6.0" effort="1000" velocity="3.0" />
  </joint>
  <link name="left_shoulder_link">
    <inertial>
      <origin xyz="-2.34187669256869E-16 -0.0259259508257144 -9.99200722162641E-16" rpy="0 0 0" />
      <mass value="0.00763663718201333" />
      <inertia ixx="9.35393567758914E-07" ixy="-1.26100331041691E-22" ixz="4.12200417999799E-09" iyy="2.02189199404243E-06" iyz="2.4695109171783E-22" izz="2.43758966616897E-06" />
    </inertial>
    <visual>
      <origin xyz="0 0 0" rpy="0 0 0" />
      <geometry>
        <mesh filename="package://k1_description/meshes/visual/left_shoulder_link.STL" />
      </geometry>
      <material name="">
        <color rgba="0.752941176470588 1 1 1" />
      </material>
    </visual>
    <collision>
      <origin xyz="0 0 0" rpy="0 0 0" />
      <geometry>
        <mesh filename="package://k1_description/meshes/collision/left_shoulder_link.STL" />
      </geometry>
    </collision>
  </link>
  <joint name="left_shoulder_joint" type="revolute">
    <origin xyz="0.026 0.00700000000000001 0.075" rpy="0 0 -1.5707963267949" />
    <parent link="base_link" />
    <child link="left_shoulder_link" />
    <axis xyz="0 1 0" />
    <limit lower="-6.0" upper="6.0" effort="1000" velocity="3.0" />
  </joint>
  <link name="left_upper_arm_link">
    <inertial>
      <origin xyz="1.56125112837913E-15 -7.08634539936526E-16 -0.0279976503716149" rpy="0 0 0" />
      <mass value="0.0404127433991118" />
      <inertia ixx="5.83338324794276E-06" ixy="-9.56686077205861E-23" ixz="1.37129632383484E-21" iyy="6.27306084712395E-06" iyz="9.15688938096202E-22" izz="5.28657199364051E-06" />
    </inertial>
    <visual>
      <origin xyz="0 0 0" rpy="0 0 0" />
      <geometry>
        <mesh filename="package://k1_description/meshes/visual/left_upper_arm_link.STL" />
      </geometry>
      <material name="">
        <color rgba="0.250980392156863 0.250980392156863 0.250980392156863 1" />
      </material>
    </visual>
    <collision>
      <origin xyz="0 0 0" rpy="0 0 0" />
      <geometry>
        <mesh filename="package://k1_description/meshes/collision/left_upper_arm_link.STL" />
      </geometry>
    </collision>
  </link>
  <joint name="left_upper_arm_joint" type="revolute">
    <origin xyz="0 -0.0349999999999999 0" rpy="0.00274508024652193 0.0285971009019818 1.57087481762947" />
    <parent link="left_shoulder_link" />
    <child link="left_upper_arm_link" />
    <axis xyz="0 1 0" />
    <limit lower="-6.0" upper="6.0" effort="1000" velocity="3.0" />
  </joint>
  <link name="left_lower_arm_link">
    <inertial>
      <origin xyz="0.0182616337014054 -0.000840716498841161 6.93889390390723E-18" rpy="0 0 0" />
      <mass value="0.0290848600660391" />
      <inertia ixx="2.72498939319332E-06" ixy="1.67669592897644E-07" ixz="-1.05879118406788E-22" iyy="4.0538898836655E-06" iyz="8.69211727428378E-22" izz="4.64311633086366E-06" />
    </inertial>
    <visual>
      <origin xyz="0 0 0" rpy="0 0 0" />
      <geometry>
        <mesh filename="package://k1_description/meshes/visual/left_lower_arm_link.STL" />
      </geometry>
      <material name="">
        <color rgba="0.250980392156863 0.250980392156863 0.250980392156863 1" />
      </material>
    </visual>
    <collision>
      <origin xyz="0 0 0" rpy="0 0 0" />
      <geometry>
        <mesh filename="package://k1_description/meshes/collision/left_lower_arm_link.STL" />
      </geometry>
    </collision>
  </link>
  <joint name="left_lower_arm_joint" type="revolute">
    <origin xyz="0 0 -0.0699999999999956" rpy="0 1.52080805151912 -1.57079632679494" />
    <parent link="left_upper_arm_link" />
    <child link="left_lower_arm_link" />
    <axis xyz="0 1 0" />
    <limit lower="-6.0" upper="6.0" effort="1000" velocity="3.0" />
  </joint>
  <link name="head_link">
    <inertial>
      <origin xyz="1.77662602571516E-05 -0.0342636340735728 5.27015314794558E-07" rpy="0 0 0" />
      <mass value="0.0901518210219852" />
      <inertia ixx="2.41005619280376E-05" ixy="-6.15798115932374E-09" ixz="1.35489424526232E-09" iyy="3.57923710083382E-05" iyz="4.62380615190815E-10" izz="3.42226307311124E-05" />
    </inertial>
    <visual>
      <origin xyz="0 0 0" rpy="0 0 0" />
      <geometry>
        <mesh filename="package://k1_description/meshes/visual/head_link.STL" />
      </geometry>
      <material name="">
        <color rgba="1 0.501960784313725 1 1" />
      </material>
    </visual>
    <collision>
      <origin xyz="0 0 0" rpy="0 0 0" />
      <geometry>
        <mesh filename="package://k1_description/meshes/collision/head_link.STL" />
      </geometry>
    </collision>
  </link>
  <joint name="head_joint" type="revolute">
    <origin xyz="0 0.011 0.071" rpy="-1.5707963267949 0 1.5707963267949" />
    <parent link="base_link" />
    <child link="head_link" />
    <axis xyz="0 1 0" />
    <limit lower="-6.0" upper="6.0" effort="1000" velocity="3.0" />
  </joint>
</robot>
